<mujoco model="monopod model">
  <!-- defaults -->
  <compiler angle="radian" coordinate="local" inertiafromgeom="true"/>
  <default>
    <!-- in this model, mass is calculated based on density -->
    <joint armature=".1" damping=".01" limited="true" solimplimit="0 .8 .03" solreflimit=".02 1" stiffness="8"/>
    <geom conaffinity="0" condim="3" contype="1" friction="1 .1 .1" rgba="0.8 0.6 .4 1" solimp="0.0 0.8 0.01" solref="0.02 1" density = "15.25"/>
    <motor ctrllimited="true" ctrlrange="-1 1"/>

    <tendon stiffness = "50"/>
    <muscle ctrllimited="true" ctrlrange="0 1" force="100" />
  </default>
  <size nstack="300000" nuser_geom="1"/>
  <option gravity="0 0 -9.81" timestep="0.005"/> <!-- timestep=0.001 to eliminate shaking -->
  <!-- sky and floor -->
  <asset>
    <texture builtin="gradient" height="100" rgb1="1 1 1" rgb2="0 0 0" type="skybox" width="100"/>
    <texture builtin="flat" height="1278" mark="cross" markrgb="1 1 1" name="texgeom" random="0.01" rgb1="0.8 0.6 0.4" rgb2="0.8 0.6 0.4" type="cube" width="127"/>
    <!-- <texture builtin="checker" height="100" name="texplane" rgb1="0 0 0" rgb2="0.8 0.8 0.8" type="2d" width="100"/> -->
    <texture builtin="flat" height="100" name="texplane" rgb1="0.4 0.26 0.16" type="2d" width="100"/>

    <!-- <material name="MatPlane" reflectance="0.5" shininess="1" specular="1" texrepeat="60 60" texture="texplane"/> -->
    <material name="MatPlane" reflectance="0" shininess="1" specular="1" texrepeat="1 1" texture="texplane"/>
    <material name="geom" texture="texgeom" texuniform="true"/>
  </asset>
  <worldbody>
    <light cutoff="100" diffuse="1 1 1" dir="-0 0 -1.3" directional="true" exponent="1" pos="0 0 1.3" specular=".1 .1 .1"/>
    <geom conaffinity="1" condim="3" material="MatPlane" name="floor" pos="0 0 0" rgba="0.8 0.8 0.8 1" size="40 40 40" type="plane"/>
    

    <!-- body -->
    <!-- torso -->
    <body name="torso" pos="0 0 .5">
      <camera name="track" mode="trackcom" pos="0 -3 0.3" xyaxes="1 0 0 0 0 1"/>
      <joint armature="0" axis="1 0 0" damping="0" limited="false" name="rootx" pos="0 0 0" stiffness="0" type="slide"/>
      <joint armature="0" axis="0 0 1" damping="0" limited="false" name="rootz" pos="0 0 0" stiffness="0" type="slide"/>
      <!-- <joint armature="0" axis="0 1 0" damping="0" limited="false" name="rooty" pos="0 0 0" stiffness="0" type="hinge"/> -->
      <geom name="torso" size=".2 .1 .05" type="box" pos = "-0.5 -0.2 0.2"/>
      <!-- <geom axisangle="0 1 0 .87" density="10" name="neck" pos=".5 0 .075" size="0.046 .075" type="capsule"/> -->
      <!-- <geom axisangle="0 1 0 1.7" density="10" name="head" pos=".6 0 .18" size="0.08 .095 0.2" type="ellipsoid"/> -->
      <!-- <geom axisangle="0 1 0 -.87" density="10" name="tail" pos="-.53 0 .075" size="0.026 .035" type="capsule"/> -->
      <!-- <site name='tip'  pos='.15 0 .11'/>-->
       
      <!-- right -->
      <!-- torso/rbthigh -->
      <site name="SITE_RB_0" pos="-0.35 -0.25 0.25" size="0.01"/>
      <site name="SITE_RB_1" pos="-0.65 -0.25 0.15" size="0.01"/>
      <site name="SITE_RB_2" pos="-0.35 -0.25 0.15" size="0.01"/>   
      <body name="rbthigh" pos="-.5 -.25 0">
        <joint axis="0 1 0" damping="1.5" name="rbthigh" pos="0 0 0" range="-1 .7" stiffness="0" type="hinge"/>
        <geom name="RB_HIP" type="cylinder" pos="0 0 0" zaxis="0 1 0" size=".075 .05" rgba="1 1 1 .5"/>
        <geom axisangle="0 1 0 .52" name="rbthigh" pos="-.07 0 -.12" size="0.046 .133" type="capsule"/>
        <!-- [cos(theta) -sin(theta); sin(theta) cos(theta)]*[x0;y0] and theta = -.52,.6, x0=.15, .05,-.05 y0=0, -.085-->
        <site name="SIDESITE_RB_0" pos="-0.1050 0 0.1179" size="0.01" rgba="0.7 0.8 0.95 .8" group="1"/>
        <site name="SIDESITE_RB_1" pos="0.1550 0 -0.0311" size="0.01" rgba="0.7 0.8 0.95 .8" group="1"/>
        <site name="SITE_RB_3" pos="0.0012 0 -0.0986" size="0.01"/>
        <site name="SITE_RB_4" pos="-0.1320 0 -.0708" size="0.01"/>
        <site name="SITE_RB_5" pos=" -.0661 0 -.1154" size="0.01"/>
        <!-- torso/rbthigh/rbshin -->
        <body name="rbshin" pos="-.14 0 -.24">
          <joint axis="0 1 0" damping="1" name="rbshin" pos="0 0 0" range="-1.2 .87" stiffness="0" type="hinge"/>
          <geom name="RB_KNEE" type="cylinder" pos="0 0 0" zaxis="0 1 0" size=".075 .05" rgba="1 1 1 .5"/>
          <geom axisangle="0 1 0 -.6" name="rbshin" pos=".065 0 -.09" rgba="0.9 0.6 0.6 1" size="0.046 .106" type="capsule"/>
          <site axisangle="0 1 0 -.6" name="rb_sensor_site" pos=".12 0 -.17" rgba="0 1 0 .1" size="0.05 .010" type="capsule"/>
          <site name="SIDESITE_RB_2" pos="-0.1238 0 -0.0847" size="0.01" rgba="0.7 0.8 0.95 .8" group="1"/>
          <site name="SIDESITE_RB_3" pos=".1238 0 0.0847" size="0.01" rgba="0.7 0.8 0.95 .8" group="1"/>
          <site name="SITE_RB_6" pos="0.0067 0 -0.0984" size="0.01"/>
          <site name="SITE_RB_7" pos="0.0893 0 -0.0419" size="0.01"/>
        </body>
      </body>
    </body>
  </worldbody>

  <tendon>
      <!-- RB -->
      <spatial name="T_RB_M0" width="0.006" rgba="0.55 0.78 0.55 1">
          <site site="SITE_RB_0"/>
          <geom geom="RB_HIP" sidesite="SIDESITE_RB_0"/>
          <site site="SITE_RB_5"/>
          <geom geom="RB_KNEE" sidesite="SIDESITE_RB_3"/>
          <site site="SITE_RB_7"/>
      </spatial>
      <spatial name="T_RB_M1" width="0.006" rgba="0.95 0.50 0.47 1">
          <site site="SITE_RB_1"/>
          <geom geom="RB_HIP" sidesite="SIDESITE_RB_1"/>
          <site site="SITE_RB_3"/>
      </spatial>
      <spatial name="T_RB_M2" width="0.006" rgba="0.45 0.49 0.83 1">
          <site site="SITE_RB_2"/>
          <geom geom="RB_HIP" sidesite="SIDESITE_RB_0"/>
          <site site="SITE_RB_4"/>
          <geom geom="RB_KNEE" sidesite="SIDESITE_RB_2"/>
          <site site="SITE_RB_6"/>
      </spatial>
    </tendon> 


  <actuator>

    <muscle name="T_RB_M0" tendon="T_RB_M0"/>
    <muscle name="T_RB_M1" tendon="T_RB_M1"/>
    <muscle name="T_RB_M2" tendon="T_RB_M2"/>
  </actuator>

  <sensor>
     <touch name="rb_sensor" site="rb_sensor_site" />
  </sensor>
</mujoco>