<mujoco model="monopod model">
  <!-- defaults -->
  <compiler angle="radian" settotalmass="5"/>

  <option timestep="0.001" integrator="implicitfast" gravity = "0 0 -9.81"/>

  <size nstack="300000" nuser_geom="1"/>

  <default>
    <joint solimplimit="0 0.8 0.03" stiffness="8" limited="true" armature="0.1" damping="0.01"/>
    <geom conaffinity="0" contype = "1" margin="0" friction ="1 0.005 0.0001" density="1000" rgba="0.8 0.6 0.4 1"/>

    <tendon stiffness="1000"/>
    <muscle ctrllimited="true" ctrlrange="0 1"/>
  </default>

  <asset>
    <texture type="skybox" builtin="gradient" rgb1="1 1 1" rgb2="0 0 0" width="100" height="600"/>
    <texture type="cube" name="texgeom" builtin="flat" mark="cross" rgb1="0.8 0.6 0.4" rgb2="0.8 0.6 0.4" markrgb="1 1 1" width="127" height="762"/>
    <texture type="2d" name="texplane" builtin="flat" rgb1="0.4 0.26 0.16" width="100" height="100"/>
    <material name="MatPlane" texture="texplane" specular="1" shininess="1"/>
    <material name="geom" texture="texgeom" texuniform="true"/>
  </asset>

  <worldbody>
    <geom name="floor" size="40 40 40" type="plane" conaffinity="1" contype = "1"  material="MatPlane" rgba="0.8 0.8 0.8 1" solimp="0 0.95 0.001 0.5 2" solref="0.05 1"/>
    <light pos="0 0 1.3" dir="0 0 -1" directional="true" cutoff="100" exponent="1" diffuse="1 1 1" specular="0.1 0.1 0.1"/>
    <body name="torso" pos="0 0 0.5">
      <joint name="rootx" pos="0 0 0" axis="1 0 0" type="slide" stiffness="0" limited="false" armature="0" damping="0"/>
      <joint name="rootz" pos="0 0 0" axis="0 0 1" type="slide" stiffness="0" limited="false" armature="0" damping="0"/>
      <geom name="torso" size="0.2 0.1 0.05" pos="-0.5 -0.25 0.2" type="box"/>
      <site name="SITE_RB_0" pos="-0.35 -0.25 0.25" size="0.01"/>
      <site name="SITE_RB_1" pos="-0.65 -0.25 0.15" size="0.01"/>
      <site name="SITE_RB_2" pos="-0.35 -0.25 0.15" size="0.01"/>
      <camera name="track" pos="0 -3 0.3" quat="0.707107 0.707107 0 0" mode="trackcom"/>
      <body name="rbthigh" pos="-0.5 -0.25 0">
        <joint name="rbthigh" pos="0 0 0" axis="0 1 0" stiffness="1" range="-1 0.7" damping="1.5" ref = "0"/>
        <geom name="RB_HIP" size="0.075 0.05" quat="0.707107 -0.707107 0 0" type="cylinder" rgba="1 1 1 0.5"/>
        <geom name="rbthigh" size="0.046 0.133" pos="-0.07 0 -0.12" quat="0.96639 0 0.257081 0" type="capsule"/>
        <site name="SIDESITE_RB_0" pos="-0.105 0 0.1179" size="0.01" group="1" rgba="0.7 0.8 0.95 0.8"/>
        <site name="SIDESITE_RB_1" pos="0.155 0 -0.0311" size="0.01" group="1" rgba="0.7 0.8 0.95 0.8"/>
        <site name="SITE_RB_3" pos="0.0012 0 -0.0986" size="0.01"/>
        <site name="SITE_RB_4" pos="-0.132 0 -0.0708" size="0.01"/>
        <site name="SITE_RB_5" pos="-0.0661 0 -0.1154" size="0.01"/>
        <body name="rbshin" pos="-0.14 0 -0.24">
          <joint name="rbshin" pos="0 0 0" axis="0 1 0" stiffness="1" range="-1.2 0.87" damping="1" ref = "0"/>
          <geom name="RB_KNEE" size="0.075 0.05" quat="0.707107 -0.707107 0 0" type="cylinder" rgba="1 1 1 0.5"/>
          <geom name="rbshin" size="0.046 0.106" pos="0.065 0 -0.09" quat="0.955336 0 -0.29552 0" type="capsule" rgba="0.9 0.6 0.6 1"/>
          <!-- <site name="rb_sensor_site" pos="0.12 0 -0.17" quat="0.955336 0 -0.29552 0" size="0.05 0.01" type="capsule" rgba="0 1 0 0.1"/> -->
          <site name="SIDESITE_RB_2" pos="-0.1238 0 -0.0847" size="0.01" group="1" rgba="0.7 0.8 0.95 0.8"/>
          <site name="SIDESITE_RB_3" pos="0.1238 0 0.0847" size="0.01" group="1" rgba="0.7 0.8 0.95 0.8"/>
          <site name="SITE_RB_6" pos="0.0067 0 -0.0984" size="0.01"/>
          <site name="SITE_RB_7" pos="0.0893 0 -0.0419" size="0.01"/>
          <body name="rbfoot" pos="0.14 0 -0.2">
            <geom name="rbfoot" type="sphere" size="0.04" pos="0 0 0" rgba="0.9 0.3 0.3 1" conaffinity = "1" contype = "1" solimp="0 0.95 0.005 0.5 2" solref="0.02 1"/>
            <site name="rbfoot_touch_sensor_site" pos="0 0 0"  size="0.04 0.01" quat="0.955336 0 -0.29552 0" type="capsule" rgba="0 1 0 0.1"/>

          </body>
        </body>
      </body>
    </body>
  </worldbody>

  <tendon>
    <spatial name="T_RB_M0" width="0.006" rgba="0.55 0.78 0.55 1">
      <site site="SITE_RB_0"/>
      <geom geom="RB_HIP" sidesite="SIDESITE_RB_0"/>
      <site site="SITE_RB_5"/>
      <geom geom="RB_KNEE" sidesite="SIDESITE_RB_3"/>
      <site site="SITE_RB_7"/>
    </spatial>
    <spatial name="T_RB_M1" width="0.006" rgba="0.95 0.5 0.47 1">
      <site site="SITE_RB_1"/>
      <geom geom="RB_HIP" sidesite="SIDESITE_RB_1"/>
      <site site="SITE_RB_3"/>
    </spatial>
    <spatial name="T_RB_M2" width="0.006" rgba="0.45 0.49 0.83 1">
      <site site="SITE_RB_2"/>
      <geom geom="RB_HIP" sidesite="SIDESITE_RB_0"/>
      <site site="SITE_RB_4"/>
      <geom geom="RB_KNEE" sidesite="SIDESITE_RB_2"/>
      <site site="SITE_RB_6"/>
    </spatial>
  </tendon>

  <actuator>
    <muscle name="T_RB_M0" tendon="T_RB_M0" lengthrange="0.459547 0.768536" range = "0.5 1.5" lmin = "0.5" lmax = "1.5" vmax ="1.6" force = "100" fpmax = "1.3" fvmax = "1.2"/>
    <muscle name="T_RB_M1" tendon="T_RB_M1" lengthrange="0.336191 0.466032" range = "0.5 1.5" lmin = "0.5" lmax = "1.5" vmax ="1.6" force = "100" fpmax = "1.3" fvmax = "1.2"/>
    <muscle name="T_RB_M2" tendon="T_RB_M2" lengthrange="0.575756 0.863523" range = "0.5 1.5" lmin = "0.5" lmax = "1.5" vmax ="1.6"  force = "250" fpmax = "1.3" fvmax = "1.2"/>
  </actuator>

  <sensor>
    <touch site="rbfoot_touch_sensor_site" name="rbfoot_touch_sensor"/>
  </sensor>
</mujoco>
